<mujoco model="gen3_dual_arm">

  <compiler angle="radian" meshdir="assets"/>

  <option integrator="implicit"/>

  <visual>
    <headlight diffuse="0.6 0.6 0.6" ambient="0.1 0.1 0.1" specular="0 0 0"/>
    <rgba haze="0.15 0.25 0.35 1"/>
    <global azimuth="120" elevation="-20"/>
  </visual>

  <default>
    <default class="visual">
      <geom type="mesh" contype="0" conaffinity="0" group="2" rgba="0.75294 0.75294 0.75294 1"/>
    </default>
    <default class="collision">
      <geom type="mesh" group="3" contype="1" conaffinity="5"/>
    </default>
    <default class="large_actuator">
      <position forcerange="-39 39"/>
    </default>
    <default class="small_actuator">
      <position forcerange="-9 9"/>
    </default>
    <site size="0.001" rgba="0.5 0.5 0.5 0.3" group="4"/>
    <default class="table_visual">
      <geom type="mesh" contype="0" conaffinity="0" group="2"/>
    </default>
    <default class="table_collision">
        <geom type="mesh" group="5" contype="1" conaffinity="3" />
    </default>
    <default class="manip_object">
        <geom rgba="0.25 0.25 0.25 1" friction="1 0.1 0.1" contype="1" conaffinity="1"/>
    </default>
  </default>

  <asset>
    <!-- Gen3 Arm -->
    <mesh name="left_base_link" file="base_link.STL"/>
    <mesh name="left_shoulder_link" file="shoulder_link.STL"/>
    <mesh name="left_half_arm_1_link" file="half_arm_1_link.STL"/>
    <mesh name="left_half_arm_2_link" file="half_arm_2_link.STL"/>
    <mesh name="left_forearm_link" file="forearm_link.STL"/>
    <mesh name="left_spherical_wrist_1_link" file="spherical_wrist_1_link.STL"/>
    <mesh name="left_spherical_wrist_2_link" file="spherical_wrist_2_link.STL"/>
    <mesh name="left_bracelet_with_vision_link" file="bracelet_with_vision_link.STL"/>

    <mesh name="right_base_link" file="base_link.STL"/>
    <mesh name="right_shoulder_link" file="shoulder_link.STL"/>
    <mesh name="right_half_arm_1_link" file="half_arm_1_link.STL"/>
    <mesh name="right_half_arm_2_link" file="half_arm_2_link.STL"/>
    <mesh name="right_forearm_link" file="forearm_link.STL"/>
    <mesh name="right_spherical_wrist_1_link" file="spherical_wrist_1_link.STL"/>
    <mesh name="right_spherical_wrist_2_link" file="spherical_wrist_2_link.STL"/>
    <mesh name="right_bracelet_with_vision_link" file="bracelet_with_vision_link.STL"/>

    <!-- Robotiq Hand -->
    <mesh name="left_robotiq_base" file="robotiq_base.stl"/>
    <mesh name="left_left_knuckle" file="left_knuckle.stl"/>
    <mesh name="left_right_knuckle" file="right_knuckle.stl"/>
    <mesh name="left_left_finger" file="left_finger.stl"/>
    <mesh name="left_right_finger" file="right_finger.stl"/>
    <mesh name="left_left_inner_knuckle" file="left_inner_knuckle.stl"/>
    <mesh name="left_right_inner_knuckle" file="right_inner_knuckle.stl"/>
    <mesh name="left_left_finger_tip" file="left_finger_tip.stl"/>
    <mesh name="left_right_finger_tip" file="right_finger_tip.stl"/>

    <mesh name="right_robotiq_base" file="robotiq_base.stl"/>
    <mesh name="right_left_knuckle" file="left_knuckle.stl"/>
    <mesh name="right_right_knuckle" file="right_knuckle.stl"/>
    <mesh name="right_left_finger" file="left_finger.stl"/>
    <mesh name="right_right_finger" file="right_finger.stl"/>
    <mesh name="right_left_inner_knuckle" file="left_inner_knuckle.stl"/>
    <mesh name="right_right_inner_knuckle" file="right_inner_knuckle.stl"/>
    <mesh name="right_left_finger_tip" file="left_finger_tip.stl"/>
    <mesh name="right_right_finger_tip" file="right_finger_tip.stl"/>

    <!-- Vention Table -->
    <mesh name="table" file="VentionAssembly.stl" scale="0.001 0.001 0.001"/>
    <material name="dark_blue_metal" rgba="0.0 0.1 0.2 1" specular="0.9" shininess="0.9" reflectance="0.5"/>

		<texture type="skybox" builtin="gradient" rgb1="0.3 0.5 0.7" rgb2="0 0 0" width="512" height="3072"/>
    <texture type="2d" name="groundplane" builtin="checker" mark="edge" rgb1="0.2 0.3 0.4" rgb2="0.1 0.2 0.3"
      markrgb="0.8 0.8 0.8" width="300" height="300"/>
    <material name="groundplane" texture="groundplane" texuniform="true" texrepeat="5 5" reflectance="0.2"/>

    <!-- Bin -->
    <mesh name="bin" file="bin.stl" scale="0.001 0.001 0.001"/>
    <material name="bin_material" rgba="0.25 0.25 0.25 1" specular="0.1" shininess="0.1" reflectance="0.05"/>
  </asset>

  <worldbody>
    <light pos="0 0 1.5" directional="true"/>
    <geom name="floor" size="0 0 0.05" type="plane" material="groundplane"/>

    <body name="table" pos="-1.1125 0.80448 -0.09654">
      <geom class="table_visual" mesh="table" quat="0.7071 0.7071 0 0" material="dark_blue_metal" />
      <geom class="table_collision" mesh="table"/>
    </body>

    <body name="left_base_link" pos="0.63017298 0 0.93657" euler="0 0 3.14">
      <inertial pos="-0.000648 -0.000166 0.084487" quat="0.999294 0.00139618 -0.0118387 0.035636" mass="1.697"
        diaginertia="0.00462407 0.00449437 0.00207755"/>
      <geom class="visual" mesh="left_base_link"/>
      <geom class="collision" mesh="left_base_link"/>
      <body name="left_shoulder_link" pos="0 0 0.15643" quat="0 1 0 0">
        <inertial pos="-2.3e-05 -0.010364 -0.07336" quat="0.707051 0.0451246 -0.0453544 0.704263" mass="1.3773"
          diaginertia="0.00488868 0.00457 0.00135132"/>
        <joint name="left_joint_1"/>
        <geom class="visual" mesh="left_shoulder_link"/>
        <geom class="collision" mesh="left_shoulder_link"/>
        <body name="left_half_arm_1_link" pos="0 0.005375 -0.12838" quat="1 1 0 0">
          <inertial pos="-4.4e-05 -0.09958 -0.013278" quat="0.482348 0.516286 -0.516862 0.483366" mass="1.1636"
            diaginertia="0.0113017 0.011088 0.00102532"/>
          <joint name="left_joint_2" range="-2.24 2.24"/>
          <geom class="visual" mesh="left_half_arm_1_link"/>
          <geom class="collision" mesh="left_half_arm_1_link"/>
          <body name="left_half_arm_2_link" pos="0 -0.21038 -0.006375" quat="1 -1 0 0">
            <inertial pos="-4.4e-05 -0.006641 -0.117892" quat="0.706144 0.0213722 -0.0209128 0.707437" mass="1.1636"
              diaginertia="0.0111633 0.010932 0.00100671"/>
            <joint name="left_joint_3"/>
            <geom class="visual" mesh="left_half_arm_2_link"/>
            <geom class="collision" mesh="left_half_arm_2_link"/>
            <body name="left_forearm_link" pos="0 0.006375 -0.21038" quat="1 1 0 0">
              <inertial pos="-1.8e-05 -0.075478 -0.015006" quat="0.483678 0.515961 -0.515859 0.483455" mass="0.9302"
                diaginertia="0.00834839 0.008147 0.000598606"/>
              <joint name="left_joint_4" range="-2.57 2.57"/>
              <geom class="visual" mesh="left_forearm_link"/>
              <geom class="collision" mesh="left_forearm_link"/>
              <body name="left_spherical_wrist_1_link" pos="0 -0.20843 -0.006375" quat="1 -1 0 0">
                <inertial pos="1e-06 -0.009432 -0.063883" quat="0.703558 0.0707492 -0.0707492 0.703558" mass="0.6781"
                  diaginertia="0.00165901 0.001596 0.000346988"/>
                <joint name="left_joint_5"/>
                <geom class="visual" mesh="left_spherical_wrist_1_link"/>
                <geom class="collision" mesh="left_spherical_wrist_1_link"/>
                <body name="left_spherical_wrist_2_link" pos="0 0.00017505 -0.10593" quat="1 1 0 0">
                  <inertial pos="1e-06 -0.045483 -0.00965" quat="0.44426 0.550121 -0.550121 0.44426" mass="0.6781"
                    diaginertia="0.00170087 0.001641 0.00035013"/>
                  <joint name="left_joint_6" range="-2.09 2.09"/>
                  <geom class="visual" mesh="left_spherical_wrist_2_link"/>
                  <geom class="collision" mesh="left_spherical_wrist_2_link"/>
                  <body name="left_bracelet_link" pos="0 -0.10593 -0.00017505" quat="1 -1 0 0">
                    <inertial pos="0.000281 0.011402 -0.029798" quat="0.394358 0.596779 -0.577293 0.393789" mass="0.5"
                      diaginertia="0.000657336 0.000587019 0.000320645"/>
                    <joint name="left_joint_7"/>
                    <geom class="visual" mesh="left_bracelet_with_vision_link"/>
                    <geom class="collision" mesh="left_bracelet_with_vision_link"/>
                    <camera name="left_wrist" pos="0 -0.05639 -0.058475" quat="0 0 0 1" fovy="41.83792730009236"
                      resolution="640 480"/>
                    <site name="left_pinch_site" pos="0 0 -0.061525" quat="0 1 0 0"/>
                    <!-- Robotiq Gripper  -->
                    <body name="left_gripper" pos="0 0 -0.064" quat="0 1 0 0">
                      <!-- Base link -->
                      <body name="left_robotiq_85_base_link">
                        <joint name="left_robotiq_85_base_joint" range="0 0"/>
                        <geom type="mesh" rgba="0.1 0.1 0.1 1" mesh="left_robotiq_base"/>
                        <inertial pos="0.0 2.274e-05 0.03232288" mass="6.6320197e-01" diaginertia="5.1617816e-04 5.8802208e-04 3.9462776e-04"/>
                        
                        <!-- Left knuckle -->
                        <body name="left_robotiq_85_left_knuckle_link" pos="0.03060114 0.0 0.05490452">
                          <joint name="left_robotiq_85_left_knuckle_joint" axis="0 -1 0" range="0.0 0.8" damping="1" armature="0.1"/>
                          <geom type="mesh" rgba="0.1 0.1 0.1 1" mesh="left_left_knuckle"/>
                          <inertial pos="0.01213197 0.0002 -0.00058647" mass="1.384773208e-02" diaginertia="3.5232e-7 2.31944e-6 2.23136e-6"/>
                          
                          <!-- Left finger -->
                          <body name="left_robotiq_85_left_finger_link" pos="0.03152616 0.0 -0.00376347">
                            <joint name="left_robotiq_85_left_finger_joint" range="0 0"/>
                            <geom type="mesh" rgba="0.1 0.1 0.1 1" mesh="left_left_finger"/>
                            <inertial pos="0.00346899 -0.00079447 0.01867121" mass="4.260376752e-02" diaginertia="1.385792000000000e-05 1.183208e-05 5.19672e-06"/>
                            
                            <!-- Left finger tip -->
                            <body name="left_robotiq_85_left_finger_tip_link" pos="0.00563134 0.0 0.04718515">
                              <joint name="left_robotiq_85_left_finger_tip_joint" axis="0 -1 0" range="0 0" damping="0.5"/>
                              <geom type="mesh" rgba="0.1 0.1 0.1 1" mesh="left_left_finger_tip" friction="100000.0 100000.0 100000.0"/>
                              <inertial pos="-0.01456706 -0.0008 0.01649701" mass="4.268588744e-02" diaginertia="1.048152e-05 1.197888e-05 4.22784e-06"/>
                            </body>
                          </body>
                        </body>
                        
                        <!-- Left inner knuckle -->
                        <body name="left_robotiq_85_left_inner_knuckle_link" pos="0.0127 0.0 0.06142">
                          <joint name="left_robotiq_85_left_inner_knuckle_joint" axis="0 -1 0" range="0 0" damping="0.5"/>
                          <geom type="mesh" rgba="0.1 0.1 0.1 1" mesh="left_left_inner_knuckle"/>
                          <inertial pos="0.01897699 0.00015001 0.02247101" mass="2.969376448e-02" diaginertia="9.57136e-06 8.69056e-06 8.19144e-06"/>
                        </body>
                        
                        <!-- Right knuckle -->
                        <body name="left_robotiq_85_right_knuckle_link" pos="-0.03060114 0.0 0.05490452">
                          <joint name="left_robotiq_85_right_knuckle_joint" axis="0 -1 0" range="-0.8 0.0" damping="1" armature="0.1"/>
                          <geom type="mesh" rgba="0.1 0.1 0.1 1" mesh="left_right_knuckle"/>
                          <inertial pos="-0.01213197 0.0002 -0.00058647" mass="1.384773208e-02" diaginertia="3.5232e-7 2.31944e-6 2.23136e-6"/>
                          
                          <!-- Right finger -->
                          <body name="left_robotiq_85_right_finger_link" pos="-0.03152616 0.0 -0.00376347">
                            <joint name="left_robotiq_85_right_finger_joint" range="0 0"/>
                            <geom type="mesh" rgba="0.1 0.1 0.1 1" mesh="left_right_finger"/>
                            <inertial pos="-0.00346899 -5.53e-06 0.01867121" mass="4.260376752000000e-02" diaginertia="1.385792e-05 1.183208e-05 5.19672e-06"/>
                            
                            <!-- Right finger tip -->
                            <body name="left_robotiq_85_right_finger_tip_link" pos="-0.00563134 0.0 0.04718515">
                              <joint name="left_robotiq_85_right_finger_tip_joint" axis="0 -1 0" range="0 0" damping="0.5"/>
                              <geom type="mesh" rgba="0.1 0.1 0.1 1" mesh="left_right_finger_tip" friction="100000.0 100000.0 100000.0"/>
                              <inertial pos="0.01456706 5e-05 0.01649701" mass="4.268588744e-02" diaginertia="1.048152e-05 1.197888e-05 4.22784e-06"/>
                            </body>
                          </body>
                        </body>
                        
                        <!-- Right inner knuckle -->
                        <body name="left_robotiq_85_right_inner_knuckle_link" pos="-0.0127 0.0 0.06142">
                          <joint name="left_robotiq_85_right_inner_knuckle_joint" axis="0 -1 0" range="0 0" damping="0.5"/>
                          <geom type="mesh" rgba="0.1 0.1 0.1 1" mesh="left_right_inner_knuckle"/>
                          <inertial pos="-0.01926824 5.001e-05 0.02222178" mass="2.969376448e-02" diaginertia="9.42456e-06 8.69056e-06 8.33824e-06"/>
                        </body>
                      </body>
                    </body>
                  </body>
                </body>
              </body>
            </body>
          </body>
        </body>
      </body>
    </body>

    <body name="right_base_link" pos="-0.63017298 0 0.93657">
      <inertial pos="-0.000648 -0.000166 0.084487" quat="0.999294 0.00139618 -0.0118387 0.035636" mass="1.697"
        diaginertia="0.00462407 0.00449437 0.00207755"/>
      <geom class="visual" mesh="right_base_link"/>
      <geom class="collision" mesh="right_base_link"/>
      <body name="right_shoulder_link" pos="0 0 0.15643" quat="0 1 0 0">
        <inertial pos="-2.3e-05 -0.010364 -0.07336" quat="0.707051 0.0451246 -0.0453544 0.704263" mass="1.3773"
          diaginertia="0.00488868 0.00457 0.00135132"/>
        <joint name="right_joint_1"/>
        <geom class="visual" mesh="right_shoulder_link"/>
        <geom class="collision" mesh="right_shoulder_link"/>
        <body name="right_half_arm_1_link" pos="0 0.005375 -0.12838" quat="1 1 0 0">
          <inertial pos="-4.4e-05 -0.09958 -0.013278" quat="0.482348 0.516286 -0.516862 0.483366" mass="1.1636"
            diaginertia="0.0113017 0.011088 0.00102532"/>
          <joint name="right_joint_2" range="-2.24 2.24"/>
          <geom class="visual" mesh="right_half_arm_1_link"/>
          <geom class="collision" mesh="right_half_arm_1_link"/>
          <body name="right_half_arm_2_link" pos="0 -0.21038 -0.006375" quat="1 -1 0 0">
            <inertial pos="-4.4e-05 -0.006641 -0.117892" quat="0.706144 0.0213722 -0.0209128 0.707437" mass="1.1636"
              diaginertia="0.0111633 0.010932 0.00100671"/>
            <joint name="right_joint_3"/>
            <geom class="visual" mesh="right_half_arm_2_link"/>
            <geom class="collision" mesh="right_half_arm_2_link"/>
            <body name="right_forearm_link" pos="0 0.006375 -0.21038" quat="1 1 0 0">
              <inertial pos="-1.8e-05 -0.075478 -0.015006" quat="0.483678 0.515961 -0.515859 0.483455" mass="0.9302"
                diaginertia="0.00834839 0.008147 0.000598606"/>
              <joint name="right_joint_4" range="-2.57 2.57"/>
              <geom class="visual" mesh="right_forearm_link"/>
              <geom class="collision" mesh="right_forearm_link"/>
              <body name="right_spherical_wrist_1_link" pos="0 -0.20843 -0.006375" quat="1 -1 0 0">
                <inertial pos="1e-06 -0.009432 -0.063883" quat="0.703558 0.0707492 -0.0707492 0.703558" mass="0.6781"
                  diaginertia="0.00165901 0.001596 0.000346988"/>
                <joint name="right_joint_5"/>
                <geom class="visual" mesh="right_spherical_wrist_1_link"/>
                <geom class="collision" mesh="right_spherical_wrist_1_link"/>
                <body name="right_spherical_wrist_2_link" pos="0 0.00017505 -0.10593" quat="1 1 0 0">
                  <inertial pos="1e-06 -0.045483 -0.00965" quat="0.44426 0.550121 -0.550121 0.44426" mass="0.6781"
                    diaginertia="0.00170087 0.001641 0.00035013"/>
                  <joint name="right_joint_6" range="-2.09 2.09"/>
                  <geom class="visual" mesh="right_spherical_wrist_2_link"/>
                  <geom class="collision" mesh="right_spherical_wrist_2_link"/>
                  <body name="right_bracelet_link" pos="0 -0.10593 -0.00017505" quat="1 -1 0 0">
                    <inertial pos="0.000281 0.011402 -0.029798" quat="0.394358 0.596779 -0.577293 0.393789" mass="0.5"
                      diaginertia="0.000657336 0.000587019 0.000320645"/>
                    <joint name="right_joint_7"/>
                    <geom class="visual" mesh="right_bracelet_with_vision_link"/>
                    <geom class="collision" mesh="right_bracelet_with_vision_link"/>
                    <camera name="right_wrist" pos="0 -0.05639 -0.058475" quat="0 0 0 1" fovy="41.83792730009236"
                      resolution="640 480"/>
                    <site name="right_pinch_site" pos="0 0 -0.061525" quat="0 1 0 0"/>

                    <!-- Robotiq Gripper  -->
                    <body name="right_gripper" pos="0 0 -0.064" quat="0 1 0 0">
                      <!-- Base link -->
                      <body name="right_robotiq_85_base_link" >
                        <joint name="right_robotiq_85_base_joint" range="0 0"/>
                        <geom type="mesh" rgba="0.1 0.1 0.1 1" mesh="right_robotiq_base"/>
                        <inertial pos="0.0 2.274e-05 0.03232288" mass="6.6320197e-01" diaginertia="5.1617816e-04 5.8802208e-04 3.9462776e-04"/>
                        
                        <!-- Left knuckle -->
                        <body name="right_robotiq_85_left_knuckle_link" pos="0.03060114 0.0 0.05490452">
                          <joint name="right_robotiq_85_left_knuckle_joint" axis="0 -1 0" range="0.0 0.8" damping="1" armature="0.1"/>
                          <geom type="mesh" rgba="0.1 0.1 0.1 1" mesh="right_left_knuckle"/>
                          <inertial pos="0.01213197 0.0002 -0.00058647" mass="1.384773208e-02" diaginertia="3.5232e-7 2.31944e-6 2.23136e-6"/>
                          
                          <!-- Left finger -->
                          <body name="right_robotiq_85_left_finger_link" pos="0.03152616 0.0 -0.00376347">
                            <joint name="right_robotiq_85_left_finger_joint" range="0 0"/>
                            <geom type="mesh" rgba="0.1 0.1 0.1 1" mesh="right_left_finger"/>
                            <inertial pos="0.00346899 -0.00079447 0.01867121" mass="4.260376752e-02" diaginertia="1.385792000000000e-05 1.183208e-05 5.19672e-06"/>
                            
                            <!-- Left finger tip -->
                            <body name="right_robotiq_85_left_finger_tip_link" pos="0.00563134 0.0 0.04718515">
                              <joint name="right_robotiq_85_left_finger_tip_joint" axis="0 -1 0" range="0 0" damping="0.5"/>
                              <geom type="mesh" rgba="0.1 0.1 0.1 1" mesh="right_left_finger_tip" friction="100000.0 100000.0 100000.0"/>
                              <inertial pos="-0.01456706 -0.0008 0.01649701" mass="4.268588744e-02" diaginertia="1.048152e-05 1.197888e-05 4.22784e-06"/>
                            </body>
                          </body>
                        </body>
                        
                        <!-- Left inner knuckle -->
                        <body name="right_robotiq_85_left_inner_knuckle_link" pos="0.0127 0.0 0.06142">
                          <joint name="right_robotiq_85_left_inner_knuckle_joint" axis="0 -1 0" range="0 0" damping="0.5"/>
                          <geom type="mesh" rgba="0.1 0.1 0.1 1" mesh="right_left_inner_knuckle"/>
                          <inertial pos="0.01897699 0.00015001 0.02247101" mass="2.969376448e-02" diaginertia="9.57136e-06 8.69056e-06 8.19144e-06"/>
                        </body>
                        
                        <!-- Right knuckle -->
                        <body name="right_robotiq_85_right_knuckle_link" pos="-0.03060114 0.0 0.05490452">
                          <joint name="right_robotiq_85_right_knuckle_joint" axis="0 -1 0" range="-0.8 0.0" damping="1" armature="0.1"/>
                          <geom type="mesh" rgba="0.1 0.1 0.1 1" mesh="right_right_knuckle"/>
                          <inertial pos="-0.01213197 0.0002 -0.00058647" mass="1.384773208e-02" diaginertia="3.5232e-7 2.31944e-6 2.23136e-6"/>
                          
                          <!-- Right finger -->
                          <body name="right_robotiq_85_right_finger_link" pos="-0.03152616 0.0 -0.00376347">
                            <joint name="right_robotiq_85_right_finger_joint" range="0 0"/>
                            <geom type="mesh" rgba="0.1 0.1 0.1 1" mesh="right_right_finger"/>
                            <inertial pos="-0.00346899 -5.53e-06 0.01867121" mass="4.260376752000000e-02" diaginertia="1.385792e-05 1.183208e-05 5.19672e-06"/>
                            
                            <!-- Right finger tip -->
                            <body name="right_robotiq_85_right_finger_tip_link" pos="-0.00563134 0.0 0.04718515">
                              <joint name="right_robotiq_85_right_finger_tip_joint" axis="0 -1 0" range="0 0" damping="0.5"/>
                              <geom type="mesh" rgba="0.1 0.1 0.1 1" mesh="right_right_finger_tip" friction="100000.0 100000.0 100000.0"/>
                              <inertial pos="0.01456706 5e-05 0.01649701" mass="4.268588744e-02" diaginertia="1.048152e-05 1.197888e-05 4.22784e-06"/>
                            </body>
                          </body>
                        </body>
                        
                        <!-- Right inner knuckle -->
                        <body name="right_robotiq_85_right_inner_knuckle_link" pos="-0.0127 0.0 0.06142">
                          <joint name="right_robotiq_85_right_inner_knuckle_joint" axis="0 -1 0" range="0 0" damping="0.5"/>
                          <geom type="mesh" rgba="0.1 0.1 0.1 1" mesh="right_right_inner_knuckle"/>
                          <inertial pos="-0.01926824 5.001e-05 0.02222178" mass="2.969376448e-02" diaginertia="9.42456e-06 8.69056e-06 8.33824e-06"/>
                        </body>
                      </body>
                    </body>
                  </body>
                </body>
              </body>
            </body>
          </body>
        </body>
      </body>
    </body>

    <body name="bin_body" pos="-0.1905 0.15875 0.9316" quat="0.7071 0.7071 0 0">
        <inertial pos="0 0 0" mass="0.68" diaginertia="0.001 0.001 0.001"/>
        <geom name="bin_visual" type="mesh" mesh="bin" material="bin_material" class="manip_object"/>
        <geom name="bin_collision" type="mesh" mesh="bin" class="manip_object" contype="1" conaffinity="1"/>
    </body>

    <geom name="dot" type="sphere" size="0.005" pos="0.186825 0 1.1716" rgba="1 0 0 0.5" contype="0" conaffinity="0" group="1"/>
    <geom name="dot_2" type="sphere" size="0.005" pos="-0.186825 0 1.1716" rgba="1 0 0 0.5" contype="0" conaffinity="0" group="1"/>
  </worldbody>

  <equality>
    <!-- First gripper constraints -->
    <joint joint1="left_robotiq_85_right_knuckle_joint" joint2="left_robotiq_85_left_knuckle_joint" polycoef="0 -1 0 0 0" solref="0.001 1"/>
    <joint joint1="left_robotiq_85_left_inner_knuckle_joint" joint2="left_robotiq_85_left_knuckle_joint" polycoef="0 1 0 0 0" solref="0.001 1"/>
    <joint joint1="left_robotiq_85_right_inner_knuckle_joint" joint2="left_robotiq_85_left_knuckle_joint" polycoef="0 -1 0 0 0" solref="0.001 1"/>
    <joint joint1="left_robotiq_85_left_finger_tip_joint" joint2="left_robotiq_85_left_knuckle_joint" polycoef="0 -1 0 0 0" solref="0.001 1"/>
    <joint joint1="left_robotiq_85_right_finger_tip_joint" joint2="left_robotiq_85_left_knuckle_joint" polycoef="0 1 0 0 0" solref="0.001 1"/>
    <!-- Second gripper constraints -->
    <joint joint1="right_robotiq_85_right_knuckle_joint" joint2="right_robotiq_85_left_knuckle_joint" polycoef="0 -1 0 0 0" solref="0.001 1"/>
    <joint joint1="right_robotiq_85_left_inner_knuckle_joint" joint2="right_robotiq_85_left_knuckle_joint" polycoef="0 1 0 0 0" solref="0.001 1"/>
    <joint joint1="right_robotiq_85_right_inner_knuckle_joint" joint2="right_robotiq_85_left_knuckle_joint" polycoef="0 -1 0 0 0" solref="0.001 1"/>
    <joint joint1="right_robotiq_85_left_finger_tip_joint" joint2="right_robotiq_85_left_knuckle_joint" polycoef="0 -1 0 0 0" solref="0.001 1"/>
    <joint joint1="right_robotiq_85_right_finger_tip_joint" joint2="right_robotiq_85_left_knuckle_joint" polycoef="0 1 0 0 0" solref="0.001 1"/>
</equality>

  <actuator>
    <!-- Gen3 Arm -->
    <position class="large_actuator" name="left_joint_1" joint="left_joint_1"/>
    <position class="large_actuator" name="left_joint_2" joint="left_joint_2"/>
    <position class="large_actuator" name="left_joint_3" joint="left_joint_3"/>
    <position class="large_actuator" name="left_joint_4" joint="left_joint_4"/>
    <position class="small_actuator" name="left_joint_5" joint="left_joint_5"/>
    <position class="small_actuator" name="left_joint_6" joint="left_joint_6"/>
    <position class="small_actuator" name="left_joint_7" joint="left_joint_7"/>

    <position class="large_actuator" name="right_joint_1" joint="right_joint_1"/>
    <position class="large_actuator" name="right_joint_2" joint="right_joint_2"/>
    <position class="large_actuator" name="right_joint_3" joint="right_joint_3"/>
    <position class="large_actuator" name="right_joint_4" joint="right_joint_4"/>
    <position class="small_actuator" name="right_joint_5" joint="right_joint_5"/>
    <position class="small_actuator" name="right_joint_6" joint="right_joint_6"/>
    <position class="small_actuator" name="right_joint_7" joint="right_joint_7"/>

    <position name="left_robotiq_85_left_knuckle_position" joint="left_robotiq_85_left_knuckle_joint" ctrlrange="0 0.8"/>
    <position name="right_robotiq_85_left_knuckle_position" joint="right_robotiq_85_left_knuckle_joint" ctrlrange="0 0.8"/>
  </actuator>

  <!-- <keyframe>
    <key name="home" qpos="0 0 0 2.53 0 0.576 1.57 0 0 0 0 0 0 0 0 0 2.53 0 0.576 1.57 0 0 0 0 0 0"/>
    <key name="home_closed" qpos="0 0 0 2.53 0 0.576 1.57 0.725 0.725 -0.725 -0.725 0.725 -0.725 0 0 0 2.53 0 0.576 1.57 0.725 0.725 -0.725 -0.725 0.725 -0.725"/>
  </keyframe> -->
</mujoco>
